Workbook

Sheet Inputs
A1: MT5 Template Controls
A3: Start Balance | B3: 88.15
A4: Deposits | B4: 0
A5: Withdrawals | B5: 0
A6: Credit Facility | B6: 0
A7: Floating P/L | B7: 0
A8: Margin | B8: 0

Sheet Positions
A1: Positions (edit here only)
A2: Fill A:X. Y:AN auto. 5 sample positions from report are preloaded.
A5: Open Time | B5: Position | C5: Symbol | D5: Type | E5: Volume | F5: Open Price | G5: S/L | H5: T/P | I5: Close Time | J5: Close Price | K5: Commission | L5: Swap | M5: Profit | N5: Entry Order ID (opt) | O5: Exit Order ID (opt) | P5: Entry Deal ID (opt) | Q5: Exit Deal ID (opt) | R5: Entry Order Price (opt) | S5: Exit Order Price (opt) | T5: Entry State | U5: Exit State | V5: Comment In | W5: Comment Out | X5: Fee | Y5: Net P/L | Z5: Balance Before | AA5: Balance After | AB5: Result Flag | AC5: Peak Balance | AD5: DD Abs | AE5: DD Rel | AF5: Abs DD From Start | AG5: Win Streak | AH5: Win Streak $ | AI5: Loss Streak | AJ5: Loss Streak $ | AK5: Win End Cnt | AL5: Win End $ | AM5: Loss End Cnt | AN5: Loss End $
A6: 46055.428 | B6: 765479379 | C6: XAUUSD.vx | D6: buy | E6: 0.01 | F6: 4603.83 | I6: 46055.429 | J6: 4618.31 | K6: 0 | L6: 0 | M6: 14.48 | N6: 765479379 | O6: 765499754 | P6: 784550662 | Q6: 784571138 | R6: market | S6: market | T6: filled | U6: filled | X6: 0 | Y6: =IF($B6="","",$K6+$L6+$M6-$X6) | Z6: =IF($B6="","",IF(ROW()=6,Inputs!$B$3+Inputs!$B$4-Inputs!$B$5,$AA5)) | AA6: =IF($B6="","",$Z6+$Y6) | AB6: =IF($B6="","",IF($Y6>0,1,IF($Y6<0,-1,0))) | AC6: =IF($B6="","",MAX($AA$6:$AA6)) | AD6: =IF($B6="","",$AC6-$AA6) | AE6: =IF($B6="","",IF($AC6=0,0,$AD6/$AC6)) | AF6: =IF($B6="","",MAX(0,(Inputs!$B$3+Inputs!$B$4-Inputs!$B$5)-$AA6)) | AG6: =IF($B6="","",IF($AB6=1,1,0)) | AH6: =IF($B6="","",IF($AB6=1,$Y6,0)) | AI6: =IF($B6="","",IF($AB6=-1,1,0)) | AJ6: =IF($B6="","",IF($AB6=-1,ABS($Y6),0)) | AK6: =IF($B6="","",IF(AND($AG6>0,OR($AB7<>1,$B7="")),$AG6,"")) | AL6: =IF($B6="","",IF(AND($AH6>0,OR($AB7<>1,$B7="")),$AH6,"")) | AM6: =IF($B6="","",IF(AND($AI6>0,OR($AB7<>-1,$B7="")),$AI6,"")) | AN6: =IF($B6="","",IF(AND($AJ6>0,OR($AB7<>-1,$B7="")),$AJ6,""))
A7: 46055.665 | B7: 768732488 | C7: XAUUSD.vx | D7: buy | E7: 0.01 | F7: 4706.46 | I7: 46055.666 | J7: 4708.37 | K7: 0 | L7: 0 | M7: 1.91 | N7: 768732488 | O7: 768750116 | P7: 787806152 | Q7: 787823039 | R7: market | S7: market | T7: filled | U7: filled | X7: 0 | Y7: =IF($B7="","",$K7+$L7+$M7-$X7) | Z7: =IF($B7="","",IF(ROW()=6,Inputs!$B$3+Inputs!$B$4-Inputs!$B$5,$AA6)) | AA7: =IF($B7="","",$Z7+$Y7) | AB7: =IF($B7="","",IF($Y7>0,1,IF($Y7<0,-1,0))) | AC7: =IF($B7="","",MAX($AA$6:$AA7)) | AD7: =IF($B7="","",$AC7-$AA7) | AE7: =IF($B7="","",IF($AC7=0,0,$AD7/$AC7)) | AF7: =IF($B7="","",MAX(0,(Inputs!$B$3+Inputs!$B$4-Inputs!$B$5)-$AA7)) | AG7: =IF($B7="","",IF($AB7=1,IF($AB6=1,$AG6+1,1),0)) | AH7: =IF($B7="","",IF($AB7=1,IF($AB6=1,$AH6+$Y7,$Y7),0)) | AI7: =IF($B7="","",IF($AB7=-1,IF($AB6=-1,$AI6+1,1),0)) | AJ7: =IF($B7="","",IF($AB7=-1,IF($AB6=-1,$AJ6+ABS($Y7),ABS($Y7)),0)) | AK7: =IF($B7="","",IF(AND($AG7>0,OR($AB8<>1,$B8="")),$AG7,"")) | AL7: =IF($B7="","",IF(AND($AH7>0,OR($AB8<>1,$B8="")),$AH7,"")) | AM7: =IF($B7="","",IF(AND($AI7>0,OR($AB8<>-1,$B8="")),$AI7,"")) | AN7: =IF($B7="","",IF(AND($AJ7>0,OR($AB8<>-1,$B8="")),$AJ7,""))
A8: 46055.761 | B8: 770503986 | C8: XAUUSD.vx | D8: sell | E8: 0.01 | F8: 4694.62 | I8: 46055.761 | J8: 4689.84 | K8: 0 | L8: 0 | M8: 4.78 | N8: 770503986 | O8: 770511666 | P8: 789621273 | Q8: 789628723 | R8: market | S8: market | T8: filled | U8: filled | X8: 0 | Y8: =IF($B8="","",$K8+$L8+$M8-$X8) | Z8: =IF($B8="","",IF(ROW()=6,Inputs!$B$3+Inputs!$B$4-Inputs!$B$5,$AA7)) | AA8: =IF($B8="","",$Z8+$Y8) | AB8: =IF($B8="","",IF($Y8>0,1,IF($Y8<0,-1,0))) | AC8: =IF($B8="","",MAX($AA$6:$AA8)) | AD8: =IF($B8="","",$AC8-$AA8) | AE8: =IF($B8="","",IF($AC8=0,0,$AD8/$AC8)) | AF8: =IF($B8="","",MAX(0,(Inputs!$B$3+Inputs!$B$4-Inputs!$B$5)-$AA8)) | AG8: =IF($B8="","",IF($AB8=1,IF($AB7=1,$AG7+1,1),0)) | AH8: =IF($B8="","",IF($AB8=1,IF($AB7=1,$AH7+$Y8,$Y8),0)) | AI8: =IF($B8="","",IF($AB8=-1,IF($AB7=-1,$AI7+1,1),0)) | AJ8: =IF($B8="","",IF($AB8=-1,IF($AB7=-1,$AJ7+ABS($Y8),ABS($Y8)),0)) | AK8: =IF($B8="","",IF(AND($AG8>0,OR($AB9<>1,$B9="")),$AG8,"")) | AL8: =IF($B8="","",IF(AND($AH8>0,OR($AB9<>1,$B9="")),$AH8,"")) | AM8: =IF($B8="","",IF(AND($AI8>0,OR($AB9<>-1,$B9="")),$AI8,"")) | AN8: =IF($B8="","",IF(AND($AJ8>0,OR($AB9<>-1,$B9="")),$AJ8,""))
A9: 46056.268 | B9: 774201034 | C9: XAUUSD.vx | D9: sell | E9: 0.01 | F9: 4806.93 | I9: 46056.272 | J9: 4812.3 | K9: 0 | L9: 0 | M9: -5.37 | N9: 774201034 | O9: 774231256 | P9: 793300215 | Q9: 793329073 | R9: market | S9: market | T9: filled | U9: filled | X9: 0 | Y9: =IF($B9="","",$K9+$L9+$M9-$X9) | Z9: =IF($B9="","",IF(ROW()=6,Inputs!$B$3+Inputs!$B$4-Inputs!$B$5,$AA8)) | AA9: =IF($B9="","",$Z9+$Y9) | AB9: =IF($B9="","",IF($Y9>0,1,IF($Y9<0,-1,0))) | AC9: =IF($B9="","",MAX($AA$6:$AA9)) | AD9: =IF($B9="","",$AC9-$AA9) | AE9: =IF($B9="","",IF($AC9=0,0,$AD9/$AC9)) | AF9: =IF($B9="","",MAX(0,(Inputs!$B$3+Inputs!$B$4-Inputs!$B$5)-$AA9)) | AG9: =IF($B9="","",IF($AB9=1,IF($AB8=1,$AG8+1,1),0)) | AH9: =IF($B9="","",IF($AB9=1,IF($AB8=1,$AH8+$Y9,$Y9),0)) | AI9: =IF($B9="","",IF($AB9=-1,IF($AB8=-1,$AI8+1,1),0)) | AJ9: =IF($B9="","",IF($AB9=-1,IF($AB8=-1,$AJ8+ABS($Y9),ABS($Y9)),0)) | AK9: =IF($B9="","",IF(AND($AG9>0,OR($AB10<>1,$B10="")),$AG9,"")) | AL9: =IF($B9="","",IF(AND($AH9>0,OR($AB10<>1,$B10="")),$AH9,"")) | AM9: =IF($B9="","",IF(AND($AI9>0,OR($AB10<>-1,$B10="")),$AI9,"")) | AN9: =IF($B9="","",IF(AND($AJ9>0,OR($AB10<>-1,$B10="")),$AJ9,""))
A10: 46056.268 | B10: 774204559 | C10: XAUUSD.vx | D10: sell | E10: 0.01 | F10: 4810.56 | I10: 46056.272 | J10: 4812.66 | K10: 0 | L10: 0 | M10: -2.1 | N10: 774204559 | O10: 774231284 | P10: 793303619 | Q10: 793329104 | R10: market | S10: market | T10: filled | U10: filled | X10: 0 | Y10: =IF($B10="","",$K10+$L10+$M10-$X10) | Z10: =IF($B10="","",IF(ROW()=6,Inputs!$B$3+Inputs!$B$4-Inputs!$B$5,$AA9)) | AA10: =IF($B10="","",$Z10+$Y10) | AB10: =IF($B10="","",IF($Y10>0,1,IF($Y10<0,-1,0))) | AC10: =IF($B10="","",MAX($AA$6:$AA10)) | AD10: =IF($B10="","",$AC10-$AA10) | AE10: =IF($B10="","",IF($AC10=0,0,$AD10/$AC10)) | AF10: =IF($B10="","",MAX(0,(Inputs!$B$3+Inputs!$B$4-Inputs!$B$5)-$AA10)) | AG10: =IF($B10="","",IF($AB10=1,IF($AB9=1,$AG9+1,1),0)) | AH10: =IF($B10="","",IF($AB10=1,IF($AB9=1,$AH9+$Y10,$Y10),0)) | AI10: =IF($B10="","",IF($AB10=-1,IF($AB9=-1,$AI9+1,1),0)) | AJ10: =IF($B10="","",IF($AB10=-1,IF($AB9=-1,$AJ9+ABS($Y10),ABS($Y10)),0)) | AK10: =IF($B10="","",IF(AND($AG10>0,OR($AB11<>1,$B11="")),$AG10,"")) | AL10: =IF($B10="","",IF(AND($AH10>0,OR($AB11<>1,$B11="")),$AH10,"")) | AM10: =IF($B10="","",IF(AND($AI10>0,OR($AB11<>-1,$B11="")),$AI10,"")) | AN10: =IF($B10="","",IF(AND($AJ10>0,OR($AB11<>-1,$B11="")),$AJ10,""))
Y11: =IF($B11="","",$K11+$L11+$M11-$X11) | Z11: =IF($B11="","",IF(ROW()=6,Inputs!$B$3+Inputs!$B$4-Inputs!$B$5,$AA10)) | AA11: =IF($B11="","",$Z11+$Y11) | AB11: =IF($B11="","",IF($Y11>0,1,IF($Y11<0,-1,0))) | AC11: =IF($B11="","",MAX($AA$6:$AA11)) | AD11: =IF($B11="","",$AC11-$AA11) | AE11: =IF($B11="","",IF($AC11=0,0,$AD11/$AC11)) | AF11: =IF($B11="","",MAX(0,(Inputs!$B$3+Inputs!$B$4-Inputs!$B$5)-$AA11)) | AG11: =IF($B11="","",IF($AB11=1,IF($AB10=1,$AG10+1,1),0)) | AH11: =IF($B11="","",IF($AB11=1,IF($AB10=1,$AH10+$Y11,$Y11),0)) | AI11: =IF($B11="","",IF($AB11=-1,IF($AB10=-1,$AI10+1,1),0)) | AJ11: =IF($B11="","",IF($AB11=-1,IF($AB10=-1,$AJ10+ABS($Y11),ABS($Y11)),0)) | AK11: =IF($B11="","",IF(AND($AG11>0,OR($AB12<>1,$B12="")),$AG11,"")) | AL11: =IF($B11="","",IF(AND($AH11>0,OR($AB12<>1,$B12="")),$AH11,"")) | AM11: =IF($B11="","",IF(AND($AI11>0,OR($AB12<>-1,$B12="")),$AI11,"")) | AN11: =IF($B11="","",IF(AND($AJ11>0,OR($AB12<>-1,$B12="")),$AJ11,""))
Y12: =IF($B12="","",$K12+$L12+$M12-$X12) | Z12: =IF($B12="","",IF(ROW()=6,Inputs!$B$3+Inputs!$B$4-Inputs!$B$5,$AA11)) | AA12: =IF($B12="","",$Z12+$Y12) | AB12: =IF($B12="","",IF($Y12>0,1,IF($Y12<0,-1,0))) | AC12: =IF($B12="","",MAX($AA$6:$AA12)) | AD12: =IF($B12="","",$AC12-$AA12) | AE12: =IF($B12="","",IF($AC12=0,0,$AD12/$AC12)) | AF12: =IF($B12="","",MAX(0,(Inputs!$B$3+Inputs!$B$4-Inputs!$B$5)-$AA12)) | AG12: =IF($B12="","",IF($AB12=1,IF($AB11=1,$AG11+1,1),0)) | AH12: =IF($B12="","",IF($AB12=1,IF($AB11=1,$AH11+$Y12,$Y12),0)) | AI12: =IF($B12="","",IF($AB12=-1,IF($AB11=-1,$AI11+1,1),0)) | AJ12: =IF($B12="","",IF($AB12=-1,IF($AB11=-1,$AJ11+ABS($Y12),ABS($Y12)),0)) | AK12: =IF($B12="","",IF(AND($AG12>0,OR($AB13<>1,$B13="")),$AG12,"")) | AL12: =IF($B12="","",IF(AND($AH12>0,OR($AB13<>1,$B13="")),$AH12,"")) | AM12: =IF($B12="","",IF(AND($AI12>0,OR($AB13<>-1,$B13="")),$AI12,"")) | AN12: =IF($B12="","",IF(AND($AJ12>0,OR($AB13<>-1,$B13="")),$AJ12,""))
Y13: =IF($B13="","",$K13+$L13+$M13-$X13) | Z13: =IF($B13="","",IF(ROW()=6,Inputs!$B$3+Inputs!$B$4-Inputs!$B$5,$AA12)) | AA13: =IF($B13="","",$Z13+$Y13) | AB13: =IF($B13="","",IF($Y13>0,1,IF($Y13<0,-1,0))) | AC13: =IF($B13="","",MAX($AA$6:$AA13)) | AD13: =IF($B13="","",$AC13-$AA13) | AE13: =IF($B13="","",IF($AC13=0,0,$AD13/$AC13)) | AF13: =IF($B13="","",MAX(0,(Inputs!$B$3+Inputs!$B$4-Inputs!$B$5)-$AA13)) | AG13: =IF($B13="","",IF($AB13=1,IF($AB12=1,$AG12+1,1),0)) | AH13: =IF($B13="","",IF($AB13=1,IF($AB12=1,$AH12+$Y13,$Y13),0)) | AI13: =IF($B13="","",IF($AB13=-1,IF($AB12=-1,$AI12+1,1),0)) | AJ13: =IF($B13="","",IF($AB13=-1,IF($AB12=-1,$AJ12+ABS($Y13),ABS($Y13)),0)) | AK13: =IF($B13="","",IF(AND($AG13>0,OR($AB14<>1,$B14="")),$AG13,"")) | AL13: =IF($B13="","",IF(AND($AH13>0,OR($AB14<>1,$B14="")),$AH13,"")) | AM13: =IF($B13="","",IF(AND($AI13>0,OR($AB14<>-1,$B14="")),$AI13,"")) | AN13: =IF($B13="","",IF(AND($AJ13>0,OR($AB14<>-1,$B14="")),$AJ13,""))
Y14: =IF($B14="","",$K14+$L14+$M14-$X14) | Z14: =IF($B14="","",IF(ROW()=6,Inputs!$B$3+Inputs!$B$4-Inputs!$B$5,$AA13)) | AA14: =IF($B14="","",$Z14+$Y14) | AB14: =IF($B14="","",IF($Y14>0,1,IF($Y14<0,-1,0))) | AC14: =IF($B14="","",MAX($AA$6:$AA14)) | AD14: =IF($B14="","",$AC14-$AA14) | AE14: =IF($B14="","",IF($AC14=0,0,$AD14/$AC14)) | AF14: =IF($B14="","",MAX(0,(Inputs!$B$3+Inputs!$B$4-Inputs!$B$5)-$AA14)) | AG14: =IF($B14="","",IF($AB14=1,IF($AB13=1,$AG13+1,1),0)) | AH14: =IF($B14="","",IF($AB14=1,IF($AB13=1,$AH13+$Y14,$Y14),0)) | AI14: =IF($B14="","",IF($AB14=-1,IF($AB13=-1,$AI13+1,1),0)) | AJ14: =IF($B14="","",IF($AB14=-1,IF($AB13=-1,$AJ13+ABS($Y14),ABS($Y14)),0)) | AK14: =IF($B14="","",IF(AND($AG14>0,OR($AB15<>1,$B15="")),$AG14,"")) | AL14: =IF($B14="","",IF(AND($AH14>0,OR($AB15<>1,$B15="")),$AH14,"")) | AM14: =IF($B14="","",IF(AND($AI14>0,OR($AB15<>-1,$B15="")),$AI14,"")) | AN14: =IF($B14="","",IF(AND($AJ14>0,OR($AB15<>-1,$B15="")),$AJ14,""))
Y15: =IF($B15="","",$K15+$L15+$M15-$X15) | Z15: =IF($B15="","",IF(ROW()=6,Inputs!$B$3+Inputs!$B$4-Inputs!$B$5,$AA14)) | AA15: =IF($B15="","",$Z15+$Y15) | AB15: =IF($B15="","",IF($Y15>0,1,IF($Y15<0,-1,0))) | AC15: =IF($B15="","",MAX($AA$6:$AA15)) | AD15: =IF($B15="","",$AC15-$AA15) | AE15: =IF($B15="","",IF($AC15=0,0,$AD15/$AC15)) | AF15: =IF($B15="","",MAX(0,(Inputs!$B$3+Inputs!$B$4-Inputs!$B$5)-$AA15)) | AG15: =IF($B15="","",IF($AB15=1,IF($AB14=1,$AG14+1,1),0)) | AH15: =IF($B15="","",IF($AB15=1,IF($AB14=1,$AH14+$Y15,$Y15),0)) | AI15: =IF($B15="","",IF($AB15=-1,IF($AB14=-1,$AI14+1,1),0)) | AJ15: =IF($B15="","",IF($AB15=-1,IF($AB14=-1,$AJ14+ABS($Y15),ABS($Y15)),0)) | AK15: =IF($B15="","",IF(AND($AG15>0,OR($AB16<>1,$B16="")),$AG15,"")) | AL15: =IF($B15="","",IF(AND($AH15>0,OR($AB16<>1,$B16="")),$AH15,"")) | AM15: =IF($B15="","",IF(AND($AI15>0,OR($AB16<>-1,$B16="")),$AI15,"")) | AN15: =IF($B15="","",IF(AND($AJ15>0,OR($AB16<>-1,$B16="")),$AJ15,""))
Y16: =IF($B16="","",$K16+$L16+$M16-$X16) | Z16: =IF($B16="","",IF(ROW()=6,Inputs!$B$3+Inputs!$B$4-Inputs!$B$5,$AA15)) | AA16: =IF($B16="","",$Z16+$Y16) | AB16: =IF($B16="","",IF($Y16>0,1,IF($Y16<0,-1,0))) | AC16: =IF($B16="","",MAX($AA$6:$AA16)) | AD16: =IF($B16="","",$AC16-$AA16) | AE16: =IF($B16="","",IF($AC16=0,0,$AD16/$AC16)) | AF16: =IF($B16="","",MAX(0,(Inputs!$B$3+Inputs!$B$4-Inputs!$B$5)-$AA16)) | AG16: =IF($B16="","",IF($AB16=1,IF($AB15=1,$AG15+1,1),0)) | AH16: =IF($B16="","",IF($AB16=1,IF($AB15=1,$AH15+$Y16,$Y16),0)) | AI16: =IF($B16="","",IF($AB16=-1,IF($AB15=-1,$AI15+1,1),0)) | AJ16: =IF($B16="","",IF($AB16=-1,IF($AB15=-1,$AJ15+ABS($Y16),ABS($Y16)),0)) | AK16: =IF($B16="","",IF(AND($AG16>0,OR($AB17<>1,$B17="")),$AG16,"")) | AL16: =IF($B16="","",IF(AND($AH16>0,OR($AB17<>1,$B17="")),$AH16,"")) | AM16: =IF($B16="","",IF(AND($AI16>0,OR($AB17<>-1,$B17="")),$AI16,"")) | AN16: =IF($B16="","",IF(AND($AJ16>0,OR($AB17<>-1,$B17="")),$AJ16,""))
Y17: =IF($B17="","",$K17+$L17+$M17-$X17) | Z17: =IF($B17="","",IF(ROW()=6,Inputs!$B$3+Inputs!$B$4-Inputs!$B$5,$AA16)) | AA17: =IF($B17="","",$Z17+$Y17) | AB17: =IF($B17="","",IF($Y17>0,1,IF($Y17<0,-1,0))) | AC17: =IF($B17="","",MAX($AA$6:$AA17)) | AD17: =IF($B17="","",$AC17-$AA17) | AE17: =IF($B17="","",IF($AC17=0,0,$AD17/$AC17)) | AF17: =IF($B17="","",MAX(0,(Inputs!$B$3+Inputs!$B$4-Inputs!$B$5)-$AA17)) | AG17: =IF($B17="","",IF($AB17=1,IF($AB16=1,$AG16+1,1),0)) | AH17: =IF($B17="","",IF($AB17=1,IF($AB16=1,$AH16+$Y17,$Y17),0)) | AI17: =IF($B17="","",IF($AB17=-1,IF($AB16=-1,$AI16+1,1),0)) | AJ17: =IF($B17="","",IF($AB17=-1,IF($AB16=-1,$AJ16+ABS($Y17),ABS($Y17)),0)) | AK17: =IF($B17="","",IF(AND($AG17>0,OR($AB18<>1,$B18="")),$AG17,"")) | AL17: =IF($B17="","",IF(AND($AH17>0,OR($AB18<>1,$B18="")),$AH17,"")) | AM17: =IF($B17="","",IF(AND($AI17>0,OR($AB18<>-1,$B18="")),$AI17,"")) | AN17: =IF($B17="","",IF(AND($AJ17>0,OR($AB18<>-1,$B18="")),$AJ17,""))
Y18: =IF($B18="","",$K18+$L18+$M18-$X18) | Z18: =IF($B18="","",IF(ROW()=6,Inputs!$B$3+Inputs!$B$4-Inputs!$B$5,$AA17)) | AA18: =IF($B18="","",$Z18+$Y18) | AB18: =IF($B18="","",IF($Y18>0,1,IF($Y18<0,-1,0))) | AC18: =IF($B18="","",MAX($AA$6:$AA18)) | AD18: =IF($B18="","",$AC18-$AA18) | AE18: =IF($B18="","",IF($AC18=0,0,$AD18/$AC18)) | AF18: =IF($B18="","",MAX(0,(Inputs!$B$3+Inputs!$B$4-Inputs!$B$5)-$AA18)) | AG18: =IF($B18="","",IF($AB18=1,IF($AB17=1,$AG17+1,1),0)) | AH18: =IF($B18="","",IF($AB18=1,IF($AB17=1,$AH17+$Y18,$Y18),0)) | AI18: =IF($B18="","",IF($AB18=-1,IF($AB17=-1,$AI17+1,1),0)) | AJ18: =IF($B18="","",IF($AB18=-1,IF($AB17=-1,$AJ17+ABS($Y18),ABS($Y18)),0)) | AK18: =IF($B18="","",IF(AND($AG18>0,OR($AB19<>1,$B19="")),$AG18,"")) | AL18: =IF($B18="","",IF(AND($AH18>0,OR($AB19<>1,$B19="")),$AH18,"")) | AM18: =IF($B18="","",IF(AND($AI18>0,OR($AB19<>-1,$B19="")),$AI18,"")) | AN18: =IF($B18="","",IF(AND($AJ18>0,OR($AB19<>-1,$B19="")),$AJ18,""))
Y19: =IF($B19="","",$K19+$L19+$M19-$X19) | Z19: =IF($B19="","",IF(ROW()=6,Inputs!$B$3+Inputs!$B$4-Inputs!$B$5,$AA18)) | AA19: =IF($B19="","",$Z19+$Y19) | AB19: =IF($B19="","",IF($Y19>0,1,IF($Y19<0,-1,0))) | AC19: =IF($B19="","",MAX($AA$6:$AA19)) | AD19: =IF($B19="","",$AC19-$AA19) | AE19: =IF($B19="","",IF($AC19=0,0,$AD19/$AC19)) | AF19: =IF($B19="","",MAX(0,(Inputs!$B$3+Inputs!$B$4-Inputs!$B$5)-$AA19)) | AG19: =IF($B19="","",IF($AB19=1,IF($AB18=1,$AG18+1,1),0)) | AH19: =IF($B19="","",IF($AB19=1,IF($AB18=1,$AH18+$Y19,$Y19),0)) | AI19: =IF($B19="","",IF($AB19=-1,IF($AB18=-1,$AI18+1,1),0)) | AJ19: =IF($B19="","",IF($AB19=-1,IF($AB18=-1,$AJ18+ABS($Y19),ABS($Y19)),0)) | AK19: =IF($B19="","",IF(AND($AG19>0,OR($AB20<>1,$B20="")),$AG19,"")) | AL19: =IF($B19="","",IF(AND($AH19>0,OR($AB20<>1,$B20="")),$AH19,"")) | AM19: =IF($B19="","",IF(AND($AI19>0,OR($AB20<>-1,$B20="")),$AI19,"")) | AN19: =IF($B19="","",IF(AND($AJ19>0,OR($AB20<>-1,$B20="")),$AJ19,""))
Y20: =IF($B20="","",$K20+$L20+$M20-$X20) | Z20: =IF($B20="","",IF(ROW()=6,Inputs!$B$3+Inputs!$B$4-Inputs!$B$5,$AA19)) | AA20: =IF($B20="","",$Z20+$Y20) | AB20: =IF($B20="","",IF($Y20>0,1,IF($Y20<0,-1,0))) | AC20: =IF($B20="","",MAX($AA$6:$AA20)) | AD20: =IF($B20="","",$AC20-$AA20) | AE20: =IF($B20="","",IF($AC20=0,0,$AD20/$AC20)) | AF20: =IF($B20="","",MAX(0,(Inputs!$B$3+Inputs!$B$4-Inputs!$B$5)-$AA20)) | AG20: =IF($B20="","",IF($AB20=1,IF($AB19=1,$AG19+1,1),0)) | AH20: =IF($B20="","",IF($AB20=1,IF($AB19=1,$AH19+$Y20,$Y20),0)) | AI20: =IF($B20="","",IF($AB20=-1,IF($AB19=-1,$AI19+1,1),0)) | AJ20: =IF($B20="","",IF($AB20=-1,IF($AB19=-1,$AJ19+ABS($Y20),ABS($Y20)),0)) | AK20: =IF($B20="","",IF(AND($AG20>0,OR($AB21<>1,$B21="")),$AG20,"")) | AL20: =IF($B20="","",IF(AND($AH20>0,OR($AB21<>1,$B21="")),$AH20,"")) | AM20: =IF($B20="","",IF(AND($AI20>0,OR($AB21<>-1,$B21="")),$AI20,"")) | AN20: =IF($B20="","",IF(AND($AJ20>0,OR($AB21<>-1,$B21="")),$AJ20,""))
Y21: =IF($B21="","",$K21+$L21+$M21-$X21) | Z21: =IF($B21="","",IF(ROW()=6,Inputs!$B$3+Inputs!$B$4-Inputs!$B$5,$AA20)) | AA21: =IF($B21="","",$Z21+$Y21) | AB21: =IF($B21="","",IF($Y21>0,1,IF($Y21<0,-1,0))) | AC21: =IF($B21="","",MAX($AA$6:$AA21)) | AD21: =IF($B21="","",$AC21-$AA21) | AE21: =IF($B21="","",IF($AC21=0,0,$AD21/$AC21)) | AF21: =IF($B21="","",MAX(0,(Inputs!$B$3+Inputs!$B$4-Inputs!$B$5)-$AA21)) | AG21: =IF($B21="","",IF($AB21=1,IF($AB20=1,$AG20+1,1),0)) | AH21: =IF($B21="","",IF($AB21=1,IF($AB20=1,$AH20+$Y21,$Y21),0)) | AI21: =IF($B21="","",IF($AB21=-1,IF($AB20=-1,$AI20+1,1),0)) | AJ21: =IF($B21="","",IF($AB21=-1,IF($AB20=-1,$AJ20+ABS($Y21),ABS($Y21)),0)) | AK21: =IF($B21="","",IF(AND($AG21>0,OR($AB22<>1,$B22="")),$AG21,"")) | AL21: =IF($B21="","",IF(AND($AH21>0,OR($AB22<>1,$B22="")),$AH21,"")) | AM21: =IF($B21="","",IF(AND($AI21>0,OR($AB22<>-1,$B22="")),$AI21,"")) | AN21: =IF($B21="","",IF(AND($AJ21>0,OR($AB22<>-1,$B22="")),$AJ21,""))
Y22: =IF($B22="","",$K22+$L22+$M22-$X22) | Z22: =IF($B22="","",IF(ROW()=6,Inputs!$B$3+Inputs!$B$4-Inputs!$B$5,$AA21)) | AA22: =IF($B22="","",$Z22+$Y22) | AB22: =IF($B22="","",IF($Y22>0,1,IF($Y22<0,-1,0))) | AC22: =IF($B22="","",MAX($AA$6:$AA22)) | AD22: =IF($B22="","",$AC22-$AA22) | AE22: =IF($B22="","",IF($AC22=0,0,$AD22/$AC22)) | AF22: =IF($B22="","",MAX(0,(Inputs!$B$3+Inputs!$B$4-Inputs!$B$5)-$AA22)) | AG22: =IF($B22="","",IF($AB22=1,IF($AB21=1,$AG21+1,1),0)) | AH22: =IF($B22="","",IF($AB22=1,IF($AB21=1,$AH21+$Y22,$Y22),0)) | AI22: =IF($B22="","",IF($AB22=-1,IF($AB21=-1,$AI21+1,1),0)) | AJ22: =IF($B22="","",IF($AB22=-1,IF($AB21=-1,$AJ21+ABS($Y22),ABS($Y22)),0)) | AK22: =IF($B22="","",IF(AND($AG22>0,OR($AB23<>1,$B23="")),$AG22,"")) | AL22: =IF($B22="","",IF(AND($AH22>0,OR($AB23<>1,$B23="")),$AH22,"")) | AM22: =IF($B22="","",IF(AND($AI22>0,OR($AB23<>-1,$B23="")),$AI22,"")) | AN22: =IF($B22="","",IF(AND($AJ22>0,OR($AB23<>-1,$B23="")),$AJ22,""))
... Y34: =IF($B34="","",$K34+$L34+$M34-$X34) | Z34: =IF($B34="","",IF(ROW()=6,Inputs!$B$3+Inputs!$B$4-Inputs!$B$5,$AA33)) | AA34: =IF($B34="","",$Z34+$Y34) | AB34: =IF($B34="","",IF($Y34>0,1,IF($Y34<0,-1,0))) | AC34: =IF($B34="","",MAX($AA$6:$AA34)) | AD34: =IF($B34="","",$AC34-$AA34) | AE34: =IF($B34="","",IF($AC34=0,0,$AD34/$AC34)) | AF34: =IF($B34="","",MAX(0,(Inputs!$B$3+Inputs!$B$4-Inputs!$B$5)-$AA34)) | AG34: =IF($B34="","",IF($AB34=1,IF($AB33=1,$AG33+1,1),0)) | AH34: =IF($B34="","",IF($AB34=1,IF($AB33=1,$AH33+$Y34,$Y34),0)) | AI34: =IF($B34="","",IF($AB34=-1,IF($AB33=-1,$AI33+1,1),0)) | AJ34: =IF($B34="","",IF($AB34=-1,IF($AB33=-1,$AJ33+ABS($Y34),ABS($Y34)),0)) | AK34: =IF($B34="","",IF(AND($AG34>0,OR($AB35<>1,$B35="")),$AG34,"")) | AL34: =IF($B34="","",IF(AND($AH34>0,OR($AB35<>1,$B35="")),$AH34,"")) | AM34: =IF($B34="","",IF(AND($AI34>0,OR($AB35<>-1,$B35="")),$AI34,"")) | AN34: =IF($B34="","",IF(AND($AJ34>0,OR($AB35<>-1,$B35="")),$AJ34,""))
Y35: =IF($B35="","",$K35+$L35+$M35-$X35) | Z35: =IF($B35="","",IF(ROW()=6,Inputs!$B$3+Inputs!$B$4-Inputs!$B$5,$AA34)) | AA35: =IF($B35="","",$Z35+$Y35) | AB35: =IF($B35="","",IF($Y35>0,1,IF($Y35<0,-1,0))) | AC35: =IF($B35="","",MAX($AA$6:$AA35)) | AD35: =IF($B35="","",$AC35-$AA35) | AE35: =IF($B35="","",IF($AC35=0,0,$AD35/$AC35)) | AF35: =IF($B35="","",MAX(0,(Inputs!$B$3+Inputs!$B$4-Inputs!$B$5)-$AA35)) | AG35: =IF($B35="","",IF($AB35=1,IF($AB34=1,$AG34+1,1),0)) | AH35: =IF($B35="","",IF($AB35=1,IF($AB34=1,$AH34+$Y35,$Y35),0)) | AI35: =IF($B35="","",IF($AB35=-1,IF($AB34=-1,$AI34+1,1),0)) | AJ35: =IF($B35="","",IF($AB35=-1,IF($AB34=-1,$AJ34+ABS($Y35),ABS($Y35)),0)) | AK35: =IF($B35="","",IF($AG35>0,$AG35,"")) | AL35: =IF($B35="","",IF($AH35>0,$AH35,"")) | AM35: =IF($B35="","",IF($AI35>0,$AI35,"")) | AN35: =IF($B35="","",IF($AJ35>0,$AJ35,""))

Sheet Summary
A1: MT5 Summary (auto from Positions)
A2: Value = live formula. Formula Ref = audit guide.
A4: Metric | B4: Value | C4: Formula Ref
A5: Balance | B5: =Inputs!$B$3+Inputs!$B$4-Inputs!$B$5+SUM(Positions!$Y$6:$Y$35) | C5: Start Balance + Deposits - Withdrawals + SUM(Net P/L)
A6: Credit Facility | B6: =Inputs!$B$6 | C6: Inputs!B6
A7: Floating P/L | B7: =Inputs!$B$7 | C7: Inputs!B7
A8: Equity | B8: =B5+B6+B7 | C8: Balance + Credit Facility + Floating P/L
A9: Free Margin | B9: =B8-B10 | C9: Equity - Margin
A10: Margin | B10: =Inputs!$B$8 | C10: Inputs!B8
A11: Margin Level | B11: =IF(B10=0,0,B8/B10) | C11: IF(Margin=0,0,Equity/Margin)
A12: Total Net Profit | B12: =SUM(Positions!$Y$6:$Y$35) | C12: SUM(Net P/L)
A13: Gross Profit | B13: =SUMIF(Positions!$Y$6:$Y$35,">0") | C13: SUMIF(Net P/L,">0")
A14: Gross Loss | B14: =SUMIF(Positions!$Y$6:$Y$35,"<0") | C14: SUMIF(Net P/L,"<0")
A15: Profit Factor | B15: =IF(ABS(B14)=0,0,B13/ABS(B14)) | C15: Gross Profit / ABS(Gross Loss)
A16: Expected Payoff | B16: =IF(B19=0,0,B12/B19) | C16: Total Net Profit / Total Trades
A17: Recovery Factor | B17: =IF(ABS(B17)=0,0,B12/ABS(B17)) | C17: Total Net Profit / ABS(Balance Drawdown Maximal)
A18: Sharpe Ratio | B18: =IFERROR(AVERAGEIF(Positions!$Y$6:$Y$35,"<>0")/STDEV.S(Positions!$Y$6:$Y$35)*SQRT(B19),0) | C18: AVERAGE(non-zero Net P/L) / STDEV.S(Net P/L) * SQRT(Total Trades)
A19: Balance Drawdown Absolute | B19: =MAX(Positions!$AF$6:$AF$35) | C19: MAX(Abs DD From Start)
A20: Balance Drawdown Maximal | B20: =MAX(Positions!$AD$6:$AD$35) | C20: MAX(Drawdown Abs)
A21: Balance Drawdown Relative | B21: =MAX(Positions!$AE$6:$AE$35) | C21: MAX(Drawdown Rel)
A22: Total Trades | B22: =COUNT(Positions!$B$6:$B$35) | C22: COUNT(Position)
A23: Short Trades (won %) | B23: =COUNTIF(Positions!$D$6:$D$35,"sell")&" ("&TEXT(IFERROR(COUNTIFS(Positions!$D$6:$D$35,"sell",Positions!$Y$6:$Y$35,">0")/COUNTIF(Positions!$D$6:$D$35,"sell"),0),"0.00%")&")" | C23: Sell trades count & win %
A24: Long Trades (won %) | B24: =COUNTIF(Positions!$D$6:$D$35,"buy")&" ("&TEXT(IFERROR(COUNTIFS(Positions!$D$6:$D$35,"buy",Positions!$Y$6:$Y$35,">0")/COUNTIF(Positions!$D$6:$D$35,"buy"),0),"0.00%")&")" | C24: Buy trades count & win %
A25: Profit Trades (% of total) | B25: =COUNTIF(Positions!$Y$6:$Y$35,">0")&" ("&TEXT(IFERROR(COUNTIF(Positions!$Y$6:$Y$35,">0")/COUNT(Positions!$B$6:$B$35),0),"0.00%")&")" | C25: Winning trades count & % total
A26: Loss Trades (% of total) | B26: =COUNTIF(Positions!$Y$6:$Y$35,"<0")&" ("&TEXT(IFERROR(COUNTIF(Positions!$Y$6:$Y$35,"<0")/COUNT(Positions!$B$6:$B$35),0),"0.00%")&")" | C26: Losing trades count & % total
A27: Largest profit trade | B27: =MAX(Positions!$Y$6:$Y$35) | C27: MAX(Net P/L)
A28: Largest loss trade | B28: =MIN(Positions!$Y$6:$Y$35) | C28: MIN(Net P/L)
A29: Average profit trade | B29: =IFERROR(AVERAGEIF(Positions!$Y$6:$Y$35,">0"),0) | C29: AVERAGEIF(Net P/L,">0")
A30: Average loss trade | B30: =IFERROR(AVERAGEIF(Positions!$Y$6:$Y$35,"<0"),0) | C30: AVERAGEIF(Net P/L,"<0")
A31: Maximum consecutive wins ($) | B31: =MAX(Positions!$AK$6:$AK$35)&" ("&TEXT(INDEX(Positions!$AL$6:$AL$35,MATCH(MAX(Positions!$AK$6:$AK$35),Positions!$AK$6:$AK$35,0)),"0.00")&")" | C31: Longest win streak count and corresponding $
A32: Maximum consecutive losses ($) | B32: =MAX(Positions!$AM$6:$AM$35)&" ("&TEXT(-INDEX(Positions!$AN$6:$AN$35,MATCH(MAX(Positions!$AM$6:$AM$35),Positions!$AM$6:$AM$35,0)),"0.00")&")" | C32: Longest loss streak count and corresponding $
A33: Maximal consecutive profit (count) | B33: =TEXT(MAX(Positions!$AL$6:$AL$35),"0.00")&" ("&INDEX(Positions!$AK$6:$AK$35,MATCH(MAX(Positions!$AL$6:$AL$35),Positions!$AL$6:$AL$35,0))&")" | C33: Largest win-streak $ and count
A34: Maximal consecutive loss (count) | B34: ="-"&TEXT(MAX(Positions!$AN$6:$AN$35),"0.00")&" ("&INDEX(Positions!$AM$6:$AM$35,MATCH(MAX(Positions!$AN$6:$AN$35),Positions!$AN$6:$AN$35,0))&")" | C34: Largest loss-streak $ and count
A35: Average consecutive wins | B35: =IFERROR(AVERAGEIF(Positions!$AK$6:$AK$35,">0"),0) | C35: AVERAGEIF(Win End Count,">0")
A36: Average consecutive losses | B36: =IFERROR(AVERAGEIF(Positions!$AM$6:$AM$35,">0"),0) | C36: AVERAGEIF(Loss End Count,">0")

Sheet Orders_Auto
A1: Orders (auto from Positions)
A3: Open Time | B3: Order | C3: Symbol | D3: Type | E3: Volume | F3: Price | G3: S / L | H3: T / P | I3: Time | J3: State | K3: Comment
A4: =IF(INDEX(Positions!$B$6:$B$35,INT((ROW()-4)/2)+1)="","",IF(MOD(ROW()-4,2)=0,INDEX(Positions!$A$6:$A$35,INT((ROW()-4)/2)+1),INDEX(Positions!$I$6:$I$35,INT((ROW()-4)/2)+1))) | B4: =IF(INDEX(Positions!$B$6:$B$35,INT((ROW()-4)/2)+1)="","",IF(MOD(ROW()-4,2)=0,IF(INDEX(Positions!$N$6:$N$35,INT((ROW()-4)/2)+1)="",INDEX(Positions!$B$6:$B$35,INT((ROW()-4)/2)+1)&"01",INDEX(Positions!$N$6:$N$35,INT((ROW()-4)/2)+1)),IF(INDEX(Positions!$O$6:$O$35,INT((ROW()-4)/2)+1)="",INDEX(Positions!$B$6:$B$35,INT((ROW()-4)/2)+1)&"02",INDEX(Positions!$O$6:$O$35,INT((ROW()-4)/2)+1)))) | C4: =IF(INDEX(Positions!$B$6:$B$35,INT((ROW()-4)/2)+1)="","",INDEX(Positions!$C$6:$C$35,INT((ROW()-4)/2)+1)) | D4: =IF(INDEX(Positions!$B$6:$B$35,INT((ROW()-4)/2)+1)="","",IF(MOD(ROW()-4,2)=0,INDEX(Positions!$D$6:$D$35,INT((ROW()-4)/2)+1),IF(INDEX(Positions!$D$6:$D$35,INT((ROW()-4)/2)+1)="buy","sell","buy"))) | E4: =IF(INDEX(Positions!$B$6:$B$35,INT((ROW()-4)/2)+1)="","",TEXT(INDEX(Positions!$E$6:$E$35,INT((ROW()-4)/2)+1),"0.00")&" / "&TEXT(INDEX(Positions!$E$6:$E$35,INT((ROW()-4)/2)+1),"0.00")) | F4: =IF(INDEX(Positions!$B$6:$B$35,INT((ROW()-4)/2)+1)="","",IF(MOD(ROW()-4,2)=0,IF(INDEX(Positions!$R$6:$R$35,INT((ROW()-4)/2)+1)="","market",INDEX(Positions!$R$6:$R$35,INT((ROW()-4)/2)+1)),IF(INDEX(Positions!$S$6:$S$35,INT((ROW()-4)/2)+1)="","market",INDEX(Positions!$S$6:$S$35,INT((ROW()-4)/2)+1)))) | G4: =IF(INDEX(Positions!$B$6:$B$35,INT((ROW()-4)/2)+1)="","",IF(MOD(ROW()-4,2)=0,INDEX(Positions!$G$6:$G$35,INT((ROW()-4)/2)+1),"")) | H4: =IF(INDEX(Positions!$B$6:$B$35,INT((ROW()-4)/2)+1)="","",IF(MOD(ROW()-4,2)=0,INDEX(Positions!$H$6:$H$35,INT((ROW()-4)/2)+1),"")) | I4: =IF(INDEX(Positions!$B$6:$B$35,INT((ROW()-4)/2)+1)="","",IF(MOD(ROW()-4,2)=0,INDEX(Positions!$A$6:$A$35,INT((ROW()-4)/2)+1),INDEX(Positions!$I$6:$I$35,INT((ROW()-4)/2)+1))) | J4: =IF(INDEX(Positions!$B$6:$B$35,INT((ROW()-4)/2)+1)="","",IF(MOD(ROW()-4,2)=0,IF(INDEX(Positions!$T$6:$T$35,INT((ROW()-4)/2)+1)="","filled",INDEX(Positions!$T$6:$T$35,INT((ROW()-4)/2)+1)),IF(INDEX(Positions!$U$6:$U$35,INT((ROW()-4)/2)+1)="","filled",INDEX(Positions!$U$6:$U$35,INT((ROW()-4)/2)+1)))) | K4: =IF(INDEX(Positions!$B$6:$B$35,INT((ROW()-4)/2)+1)="","",IF(MOD(ROW()-4,2)=0,INDEX(Positions!$V$6:$V$35,INT((ROW()-4)/2)+1),INDEX(Positions!$W$6:$W$35,INT((ROW()-4)/2)+1)))
A5: =IF(INDEX(Positions!$B$6:$B$35,INT((ROW()-4)/2)+1)="","",IF(MOD(ROW()-4,2)=0,INDEX(Positions!$A$6:$A$35,INT((ROW()-4)/2)+1),INDEX(Positions!$I$6:$I$35,INT((ROW()-4)/2)+1))) | B5: =IF(INDEX(Positions!$B$6:$B$35,INT((ROW()-4)/2)+1)="","",IF(MOD(ROW()-4,2)=0,IF(INDEX(Positions!$N$6:$N$35,INT((ROW()-4)/2)+1)="",INDEX(Positions!$B$6:$B$35,INT((ROW()-4)/2)+1)&"01",INDEX(Positions!$N$6:$N$35,INT((ROW()-4)/2)+1)),IF(INDEX(Positions!$O$6:$O$35,INT((ROW()-4)/2)+1)="",INDEX(Positions!$B$6:$B$35,INT((ROW()-4)/2)+1)&"02",INDEX(Positions!$O$6:$O$35,INT((ROW()-4)/2)+1)))) | C5: =IF(INDEX(Positions!$B$6:$B$35,INT((ROW()-4)/2)+1)="","",INDEX(Positions!$C$6:$C$35,INT((ROW()-4)/2)+1)) | D5: =IF(INDEX(Positions!$B$6:$B$35,INT((ROW()-4)/2)+1)="","",IF(MOD(ROW()-4,2)=0,INDEX(Positions!$D$6:$D$35,INT((ROW()-4)/2)+1),IF(INDEX(Positions!$D$6:$D$35,INT((ROW()-4)/2)+1)="buy","sell","buy"))) | E5: =IF(INDEX(Positions!$B$6:$B$35,INT((ROW()-4)/2)+1)="","",TEXT(INDEX(Positions!$E$6:$E$35,INT((ROW()-4)/2)+1),"0.00")&" / "&TEXT(INDEX(Positions!$E$6:$E$35,INT((ROW()-4)/2)+1),"0.00")) | F5: =IF(INDEX(Positions!$B$6:$B$35,INT((ROW()-4)/2)+1)="","",IF(MOD(ROW()-4,2)=0,IF(INDEX(Positions!$R$6:$R$35,INT((ROW()-4)/2)+1)="","market",INDEX(Positions!$R$6:$R$35,INT((ROW()-4)/2)+1)),IF(INDEX(Positions!$S$6:$S$35,INT((ROW()-4)/2)+1)="","market",INDEX(Positions!$S$6:$S$35,INT((ROW()-4)/2)+1)))) | G5: =IF(INDEX(Positions!$B$6:$B$35,INT((ROW()-4)/2)+1)="","",IF(MOD(ROW()-4,2)=0,INDEX(Positions!$G$6:$G$35,INT((ROW()-4)/2)+1),"")) | H5: =IF(INDEX(Positions!$B$6:$B$35,INT((ROW()-4)/2)+1)="","",IF(MOD(ROW()-4,2)=0,INDEX(Positions!$H$6:$H$35,INT((ROW()-4)/2)+1),"")) | I5: =IF(INDEX(Positions!$B$6:$B$35,INT((ROW()-4)/2)+1)="","",IF(MOD(ROW()-4,2)=0,INDEX(Positions!$A$6:$A$35,INT((ROW()-4)/2)+1),INDEX(Positions!$I$6:$I$35,INT((ROW()-4)/2)+1))) | J5: =IF(INDEX(Positions!$B$6:$B$35,INT((ROW()-4)/2)+1)="","",IF(MOD(ROW()-4,2)=0,IF(INDEX(Positions!$T$6:$T$35,INT((ROW()-4)/2)+1)="","filled",INDEX(Positions!$T$6:$T$35,INT((ROW()-4)/2)+1)),IF(INDEX(Positions!$U$6:$U$35,INT((ROW()-4)/2)+1)="","filled",INDEX(Positions!$U$6:$U$35,INT((ROW()-4)/2)+1)))) | K5: =IF(INDEX(Positions!$B$6:$B$35,INT((ROW()-4)/2)+1)="","",IF(MOD(ROW()-4,2)=0,INDEX(Positions!$V$6:$V$35,INT((ROW()-4)/2)+1),INDEX(Positions!$W$6:$W$35,INT((ROW()-4)/2)+1)))
A6: =IF(INDEX(Positions!$B$6:$B$35,INT((ROW()-4)/2)+1)="","",IF(MOD(ROW()-4,2)=0,INDEX(Positions!$A$6:$A$35,INT((ROW()-4)/2)+1),INDEX(Positions!$I$6:$I$35,INT((ROW()-4)/2)+1))) | B6: =IF(INDEX(Positions!$B$6:$B$35,INT((ROW()-4)/2)+1)="","",IF(MOD(ROW()-4,2)=0,IF(INDEX(Positions!$N$6:$N$35,INT((ROW()-4)/2)+1)="",INDEX(Positions!$B$6:$B$35,INT((ROW()-4)/2)+1)&"01",INDEX(Positions!$N$6:$N$35,INT((ROW()-4)/2)+1)),IF(INDEX(Positions!$O$6:$O$35,INT((ROW()-4)/2)+1)="",INDEX(Positions!$B$6:$B$35,INT((ROW()-4)/2)+1)&"02",INDEX(Positions!$O$6:$O$35,INT((ROW()-4)/2)+1)))) | C6: =IF(INDEX(Positions!$B$6:$B$35,INT((ROW()-4)/2)+1)="","",INDEX(Positions!$C$6:$C$35,INT((ROW()-4)/2)+1)) | D6: =IF(INDEX(Positions!$B$6:$B$35,INT((ROW()-4)/2)+1)="","",IF(MOD(ROW()-4,2)=0,INDEX(Positions!$D$6:$D$35,INT((ROW()-4)/2)+1),IF(INDEX(Positions!$D$6:$D$35,INT((ROW()-4)/2)+1)="buy","sell","buy"))) | E6: =IF(INDEX(Positions!$B$6:$B$35,INT((ROW()-4)/2)+1)="","",TEXT(INDEX(Positions!$E$6:$E$35,INT((ROW()-4)/2)+1),"0.00")&" / "&TEXT(INDEX(Positions!$E$6:$E$35,INT((ROW()-4)/2)+1),"0.00")) | F6: =IF(INDEX(Positions!$B$6:$B$35,INT((ROW()-4)/2)+1)="","",IF(MOD(ROW()-4,2)=0,IF(INDEX(Positions!$R$6:$R$35,INT((ROW()-4)/2)+1)="","market",INDEX(Positions!$R$6:$R$35,INT((ROW()-4)/2)+1)),IF(INDEX(Positions!$S$6:$S$35,INT((ROW()-4)/2)+1)="","market",INDEX(Positions!$S$6:$S$35,INT((ROW()-4)/2)+1)))) | G6: =IF(INDEX(Positions!$B$6:$B$35,INT((ROW()-4)/2)+1)="","",IF(MOD(ROW()-4,2)=0,INDEX(Positions!$G$6:$G$35,INT((ROW()-4)/2)+1),"")) | H6: =IF(INDEX(Positions!$B$6:$B$35,INT((ROW()-4)/2)+1)="","",IF(MOD(ROW()-4,2)=0,INDEX(Positions!$H$6:$H$35,INT((ROW()-4)/2)+1),"")) | I6: =IF(INDEX(Positions!$B$6:$B$35,INT((ROW()-4)/2)+1)="","",IF(MOD(ROW()-4,2)=0,INDEX(Positions!$A$6:$A$35,INT((ROW()-4)/2)+1),INDEX(Positions!$I$6:$I$35,INT((ROW()-4)/2)+1))) | J6: =IF(INDEX(Positions!$B$6:$B$35,INT((ROW()-4)/2)+1)="","",IF(MOD(ROW()-4,2)=0,IF(INDEX(Positions!$T$6:$T$35,INT((ROW()-4)/2)+1)="","filled",INDEX(Positions!$T$6:$T$35,INT((ROW()-4)/2)+1)),IF(INDEX(Positions!$U$6:$U$35,INT((ROW()-4)/2)+1)="","filled",INDEX(Positions!$U$6:$U$35,INT((ROW()-4)/2)+1)))) | K6: =IF(INDEX(Positions!$B$6:$B$35,INT((ROW()-4)/2)+1)="","",IF(MOD(ROW()-4,2)=0,INDEX(Positions!$V$6:$V$35,INT((ROW()-4)/2)+1),INDEX(Positions!$W$6:$W$35,INT((ROW()-4)/2)+1)))
A7: =IF(INDEX(Positions!$B$6:$B$35,INT((ROW()-4)/2)+1)="","",IF(MOD(ROW()-4,2)=0,INDEX(Positions!$A$6:$A$35,INT((ROW()-4)/2)+1),INDEX(Positions!$I$6:$I$35,INT((ROW()-4)/2)+1))) | B7: =IF(INDEX(Positions!$B$6:$B$35,INT((ROW()-4)/2)+1)="","",IF(MOD(ROW()-4,2)=0,IF(INDEX(Positions!$N$6:$N$35,INT((ROW()-4)/2)+1)="",INDEX(Positions!$B$6:$B$35,INT((ROW()-4)/2)+1)&"01",INDEX(Positions!$N$6:$N$35,INT((ROW()-4)/2)+1)),IF(INDEX(Positions!$O$6:$O$35,INT((ROW()-4)/2)+1)="",INDEX(Positions!$B$6:$B$35,INT((ROW()-4)/2)+1)&"02",INDEX(Positions!$O$6:$O$35,INT((ROW()-4)/2)+1)))) | C7: =IF(INDEX(Positions!$B$6:$B$35,INT((ROW()-4)/2)+1)="","",INDEX(Positions!$C$6:$C$35,INT((ROW()-4)/2)+1)) | D7: =IF(INDEX(Positions!$B$6:$B$35,INT((ROW()-4)/2)+1)="","",IF(MOD(ROW()-4,2)=0,INDEX(Positions!$D$6:$D$35,INT((ROW()-4)/2)+1),IF(INDEX(Positions!$D$6:$D$35,INT((ROW()-4)/2)+1)="buy","sell","buy"))) | E7: =IF(INDEX(Positions!$B$6:$B$35,INT((ROW()-4)/2)+1)="","",TEXT(INDEX(Positions!$E$6:$E$35,INT((ROW()-4)/2)+1),"0.00")&" / "&TEXT(INDEX(Positions!$E$6:$E$35,INT((ROW()-4)/2)+1),"0.00")) | F7: =IF(INDEX(Positions!$B$6:$B$35,INT((ROW()-4)/2)+1)="","",IF(MOD(ROW()-4,2)=0,IF(INDEX(Positions!$R$6:$R$35,INT((ROW()-4)/2)+1)="","market",INDEX(Positions!$R$6:$R$35,INT((ROW()-4)/2)+1)),IF(INDEX(Positions!$S$6:$S$35,INT((ROW()-4)/2)+1)="","market",INDEX(Positions!$S$6:$S$35,INT((ROW()-4)/2)+1)))) | G7: =IF(INDEX(Positions!$B$6:$B$35,INT((ROW()-4)/2)+1)="","",IF(MOD(ROW()-4,2)=0,INDEX(Positions!$G$6:$G$35,INT((ROW()-4)/2)+1),"")) | H7: =IF(INDEX(Positions!$B$6:$B$35,INT((ROW()-4)/2)+1)="","",IF(MOD(ROW()-4,2)=0,INDEX(Positions!$H$6:$H$35,INT((ROW()-4)/2)+1),"")) | I7: =IF(INDEX(Positions!$B$6:$B$35,INT((ROW()-4)/2)+1)="","",IF(MOD(ROW()-4,2)=0,INDEX(Positions!$A$6:$A$35,INT((ROW()-4)/2)+1),INDEX(Positions!$I$6:$I$35,INT((ROW()-4)/2)+1))) | J7: =IF(INDEX(Positions!$B$6:$B$35,INT((ROW()-4)/2)+1)="","",IF(MOD(ROW()-4,2)=0,IF(INDEX(Positions!$T$6:$T$35,INT((ROW()-4)/2)+1)="","filled",INDEX(Positions!$T$6:$T$35,INT((ROW()-4)/2)+1)),IF(INDEX(Positions!$U$6:$U$35,INT((ROW()-4)/2)+1)="","filled",INDEX(Positions!$U$6:$U$35,INT((ROW()-4)/2)+1)))) | K7: =IF(INDEX(Positions!$B$6:$B$35,INT((ROW()-4)/2)+1)="","",IF(MOD(ROW()-4,2)=0,INDEX(Positions!$V$6:$V$35,INT((ROW()-4)/2)+1),INDEX(Positions!$W$6:$W$35,INT((ROW()-4)/2)+1)))
A8: =IF(INDEX(Positions!$B$6:$B$35,INT((ROW()-4)/2)+1)="","",IF(MOD(ROW()-4,2)=0,INDEX(Positions!$A$6:$A$35,INT((ROW()-4)/2)+1),INDEX(Positions!$I$6:$I$35,INT((ROW()-4)/2)+1))) | B8: =IF(INDEX(Positions!$B$6:$B$35,INT((ROW()-4)/2)+1)="","",IF(MOD(ROW()-4,2)=0,IF(INDEX(Positions!$N$6:$N$35,INT((ROW()-4)/2)+1)="",INDEX(Positions!$B$6:$B$35,INT((ROW()-4)/2)+1)&"01",INDEX(Positions!$N$6:$N$35,INT((ROW()-4)/2)+1)),IF(INDEX(Positions!$O$6:$O$35,INT((ROW()-4)/2)+1)="",INDEX(Positions!$B$6:$B$35,INT((ROW()-4)/2)+1)&"02",INDEX(Positions!$O$6:$O$35,INT((ROW()-4)/2)+1)))) | C8: =IF(INDEX(Positions!$B$6:$B$35,INT((ROW()-4)/2)+1)="","",INDEX(Positions!$C$6:$C$35,INT((ROW()-4)/2)+1)) | D8: =IF(INDEX(Positions!$B$6:$B$35,INT((ROW()-4)/2)+1)="","",IF(MOD(ROW()-4,2)=0,INDEX(Positions!$D$6:$D$35,INT((ROW()-4)/2)+1),IF(INDEX(Positions!$D$6:$D$35,INT((ROW()-4)/2)+1)="buy","sell","buy"))) | E8: =IF(INDEX(Positions!$B$6:$B$35,INT((ROW()-4)/2)+1)="","",TEXT(INDEX(Positions!$E$6:$E$35,INT((ROW()-4)/2)+1),"0.00")&" / "&TEXT(INDEX(Positions!$E$6:$E$35,INT((ROW()-4)/2)+1),"0.00")) | F8: =IF(INDEX(Positions!$B$6:$B$35,INT((ROW()-4)/2)+1)="","",IF(MOD(ROW()-4,2)=0,IF(INDEX(Positions!$R$6:$R$35,INT((ROW()-4)/2)+1)="","market",INDEX(Positions!$R$6:$R$35,INT((ROW()-4)/2)+1)),IF(INDEX(Positions!$S$6:$S$35,INT((ROW()-4)/2)+1)="","market",INDEX(Positions!$S$6:$S$35,INT((ROW()-4)/2)+1)))) | G8: =IF(INDEX(Positions!$B$6:$B$35,INT((ROW()-4)/2)+1)="","",IF(MOD(ROW()-4,2)=0,INDEX(Positions!$G$6:$G$35,INT((ROW()-4)/2)+1),"")) | H8: =IF(INDEX(Positions!$B$6:$B$35,INT((ROW()-4)/2)+1)="","",IF(MOD(ROW()-4,2)=0,INDEX(Positions!$H$6:$H$35,INT((ROW()-4)/2)+1),"")) | I8: =IF(INDEX(Positions!$B$6:$B$35,INT((ROW()-4)/2)+1)="","",IF(MOD(ROW()-4,2)=0,INDEX(Positions!$A$6:$A$35,INT((ROW()-4)/2)+1),INDEX(Positions!$I$6:$I$35,INT((ROW()-4)/2)+1))) | J8: =IF(INDEX(Positions!$B$6:$B$35,INT((ROW()-4)/2)+1)="","",IF(MOD(ROW()-4,2)=0,IF(INDEX(Positions!$T$6:$T$35,INT((ROW()-4)/2)+1)="","filled",INDEX(Positions!$T$6:$T$35,INT((ROW()-4)/2)+1)),IF(INDEX(Positions!$U$6:$U$35,INT((ROW()-4)/2)+1)="","filled",INDEX(Positions!$U$6:$U$35,INT((ROW()-4)/2)+1)))) | K8: =IF(INDEX(Positions!$B$6:$B$35,INT((ROW()-4)/2)+1)="","",IF(MOD(ROW()-4,2)=0,INDEX(Positions!$V$6:$V$35,INT((ROW()-4)/2)+1),INDEX(Positions!$W$6:$W$35,INT((ROW()-4)/2)+1)))
A9: =IF(INDEX(Positions!$B$6:$B$35,INT((ROW()-4)/2)+1)="","",IF(MOD(ROW()-4,2)=0,INDEX(Positions!$A$6:$A$35,INT((ROW()-4)/2)+1),INDEX(Positions!$I$6:$I$35,INT((ROW()-4)/2)+1))) | B9: =IF(INDEX(Positions!$B$6:$B$35,INT((ROW()-4)/2)+1)="","",IF(MOD(ROW()-4,2)=0,IF(INDEX(Positions!$N$6:$N$35,INT((ROW()-4)/2)+1)="",INDEX(Positions!$B$6:$B$35,INT((ROW()-4)/2)+1)&"01",INDEX(Positions!$N$6:$N$35,INT((ROW()-4)/2)+1)),IF(INDEX(Positions!$O$6:$O$35,INT((ROW()-4)/2)+1)="",INDEX(Positions!$B$6:$B$35,INT((ROW()-4)/2)+1)&"02",INDEX(Positions!$O$6:$O$35,INT((ROW()-4)/2)+1)))) | C9: =IF(INDEX(Positions!$B$6:$B$35,INT((ROW()-4)/2)+1)="","",INDEX(Positions!$C$6:$C$35,INT((ROW()-4)/2)+1)) | D9: =IF(INDEX(Positions!$B$6:$B$35,INT((ROW()-4)/2)+1)="","",IF(MOD(ROW()-4,2)=0,INDEX(Positions!$D$6:$D$35,INT((ROW()-4)/2)+1),IF(INDEX(Positions!$D$6:$D$35,INT((ROW()-4)/2)+1)="buy","sell","buy"))) | E9: =IF(INDEX(Positions!$B$6:$B$35,INT((ROW()-4)/2)+1)="","",TEXT(INDEX(Positions!$E$6:$E$35,INT((ROW()-4)/2)+1),"0.00")&" / "&TEXT(INDEX(Positions!$E$6:$E$35,INT((ROW()-4)/2)+1),"0.00")) | F9: =IF(INDEX(Positions!$B$6:$B$35,INT((ROW()-4)/2)+1)="","",IF(MOD(ROW()-4,2)=0,IF(INDEX(Positions!$R$6:$R$35,INT((ROW()-4)/2)+1)="","market",INDEX(Positions!$R$6:$R$35,INT((ROW()-4)/2)+1)),IF(INDEX(Positions!$S$6:$S$35,INT((ROW()-4)/2)+1)="","market",INDEX(Positions!$S$6:$S$35,INT((ROW()-4)/2)+1)))) | G9: =IF(INDEX(Positions!$B$6:$B$35,INT((ROW()-4)/2)+1)="","",IF(MOD(ROW()-4,2)=0,INDEX(Positions!$G$6:$G$35,INT((ROW()-4)/2)+1),"")) | H9: =IF(INDEX(Positions!$B$6:$B$35,INT((ROW()-4)/2)+1)="","",IF(MOD(ROW()-4,2)=0,INDEX(Positions!$H$6:$H$35,INT((ROW()-4)/2)+1),"")) | I9: =IF(INDEX(Positions!$B$6:$B$35,INT((ROW()-4)/2)+1)="","",IF(MOD(ROW()-4,2)=0,INDEX(Positions!$A$6:$A$35,INT((ROW()-4)/2)+1),INDEX(Positions!$I$6:$I$35,INT((ROW()-4)/2)+1))) | J9: =IF(INDEX(Positions!$B$6:$B$35,INT((ROW()-4)/2)+1)="","",IF(MOD(ROW()-4,2)=0,IF(INDEX(Positions!$T$6:$T$35,INT((ROW()-4)/2)+1)="","filled",INDEX(Positions!$T$6:$T$35,INT((ROW()-4)/2)+1)),IF(INDEX(Positions!$U$6:$U$35,INT((ROW()-4)/2)+1)="","filled",INDEX(Positions!$U$6:$U$35,INT((ROW()-4)/2)+1)))) | K9: =IF(INDEX(Positions!$B$6:$B$35,INT((ROW()-4)/2)+1)="","",IF(MOD(ROW()-4,2)=0,INDEX(Positions!$V$6:$V$35,INT((ROW()-4)/2)+1),INDEX(Positions!$W$6:$W$35,INT((ROW()-4)/2)+1)))
A10: =IF(INDEX(Positions!$B$6:$B$35,INT((ROW()-4)/2)+1)="","",IF(MOD(ROW()-4,2)=0,INDEX(Positions!$A$6:$A$35,INT((ROW()-4)/2)+1),INDEX(Positions!$I$6:$I$35,INT((ROW()-4)/2)+1))) | B10: =IF(INDEX(Positions!$B$6:$B$35,INT((ROW()-4)/2)+1)="","",IF(MOD(ROW()-4,2)=0,IF(INDEX(Positions!$N$6:$N$35,INT((ROW()-4)/2)+1)="",INDEX(Positions!$B$6:$B$35,INT((ROW()-4)/2)+1)&"01",INDEX(Positions!$N$6:$N$35,INT((ROW()-4)/2)+1)),IF(INDEX(Positions!$O$6:$O$35,INT((ROW()-4)/2)+1)="",INDEX(Positions!$B$6:$B$35,INT((ROW()-4)/2)+1)&"02",INDEX(Positions!$O$6:$O$35,INT((ROW()-4)/2)+1)))) | C10: =IF(INDEX(Positions!$B$6:$B$35,INT((ROW()-4)/2)+1)="","",INDEX(Positions!$C$6:$C$35,INT((ROW()-4)/2)+1)) | D10: =IF(INDEX(Positions!$B$6:$B$35,INT((ROW()-4)/2)+1)="","",IF(MOD(ROW()-4,2)=0,INDEX(Positions!$D$6:$D$35,INT((ROW()-4)/2)+1),IF(INDEX(Positions!$D$6:$D$35,INT((ROW()-4)/2)+1)="buy","sell","buy"))) | E10: =IF(INDEX(Positions!$B$6:$B$35,INT((ROW()-4)/2)+1)="","",TEXT(INDEX(Positions!$E$6:$E$35,INT((ROW()-4)/2)+1),"0.00")&" / "&TEXT(INDEX(Positions!$E$6:$E$35,INT((ROW()-4)/2)+1),"0.00")) | F10: =IF(INDEX(Positions!$B$6:$B$35,INT((ROW()-4)/2)+1)="","",IF(MOD(ROW()-4,2)=0,IF(INDEX(Positions!$R$6:$R$35,INT((ROW()-4)/2)+1)="","market",INDEX(Positions!$R$6:$R$35,INT((ROW()-4)/2)+1)),IF(INDEX(Positions!$S$6:$S$35,INT((ROW()-4)/2)+1)="","market",INDEX(Positions!$S$6:$S$35,INT((ROW()-4)/2)+1)))) | G10: =IF(INDEX(Positions!$B$6:$B$35,INT((ROW()-4)/2)+1)="","",IF(MOD(ROW()-4,2)=0,INDEX(Positions!$G$6:$G$35,INT((ROW()-4)/2)+1),"")) | H10: =IF(INDEX(Positions!$B$6:$B$35,INT((ROW()-4)/2)+1)="","",IF(MOD(ROW()-4,2)=0,INDEX(Positions!$H$6:$H$35,INT((ROW()-4)/2)+1),"")) | I10: =IF(INDEX(Positions!$B$6:$B$35,INT((ROW()-4)/2)+1)="","",IF(MOD(ROW()-4,2)=0,INDEX(Positions!$A$6:$A$35,INT((ROW()-4)/2)+1),INDEX(Positions!$I$6:$I$35,INT((ROW()-4)/2)+1))) | J10: =IF(INDEX(Positions!$B$6:$B$35,INT((ROW()-4)/2)+1)="","",IF(MOD(ROW()-4,2)=0,IF(INDEX(Positions!$T$6:$T$35,INT((ROW()-4)/2)+1)="","filled",INDEX(Positions!$T$6:$T$35,INT((ROW()-4)/2)+1)),IF(INDEX(Positions!$U$6:$U$35,INT((ROW()-4)/2)+1)="","filled",INDEX(Positions!$U$6:$U$35,INT((ROW()-4)/2)+1)))) | K10: =IF(INDEX(Positions!$B$6:$B$35,INT((ROW()-4)/2)+1)="","",IF(MOD(ROW()-4,2)=0,INDEX(Positions!$V$6:$V$35,INT((ROW()-4)/2)+1),INDEX(Positions!$W$6:$W$35,INT((ROW()-4)/2)+1)))
A11: =IF(INDEX(Positions!$B$6:$B$35,INT((ROW()-4)/2)+1)="","",IF(MOD(ROW()-4,2)=0,INDEX(Positions!$A$6:$A$35,INT((ROW()-4)/2)+1),INDEX(Positions!$I$6:$I$35,INT((ROW()-4)/2)+1))) | B11: =IF(INDEX(Positions!$B$6:$B$35,INT((ROW()-4)/2)+1)="","",IF(MOD(ROW()-4,2)=0,IF(INDEX(Positions!$N$6:$N$35,INT((ROW()-4)/2)+1)="",INDEX(Positions!$B$6:$B$35,INT((ROW()-4)/2)+1)&"01",INDEX(Positions!$N$6:$N$35,INT((ROW()-4)/2)+1)),IF(INDEX(Positions!$O$6:$O$35,INT((ROW()-4)/2)+1)="",INDEX(Positions!$B$6:$B$35,INT((ROW()-4)/2)+1)&"02",INDEX(Positions!$O$6:$O$35,INT((ROW()-4)/2)+1)))) | C11: =IF(INDEX(Positions!$B$6:$B$35,INT((ROW()-4)/2)+1)="","",INDEX(Positions!$C$6:$C$35,INT((ROW()-4)/2)+1)) | D11: =IF(INDEX(Positions!$B$6:$B$35,INT((ROW()-4)/2)+1)="","",IF(MOD(ROW()-4,2)=0,INDEX(Positions!$D$6:$D$35,INT((ROW()-4)/2)+1),IF(INDEX(Positions!$D$6:$D$35,INT((ROW()-4)/2)+1)="buy","sell","buy"))) | E11: =IF(INDEX(Positions!$B$6:$B$35,INT((ROW()-4)/2)+1)="","",TEXT(INDEX(Positions!$E$6:$E$35,INT((ROW()-4)/2)+1),"0.00")&" / "&TEXT(INDEX(Positions!$E$6:$E$35,INT((ROW()-4)/2)+1),"0.00")) | F11: =IF(INDEX(Positions!$B$6:$B$35,INT((ROW()-4)/2)+1)="","",IF(MOD(ROW()-4,2)=0,IF(INDEX(Positions!$R$6:$R$35,INT((ROW()-4)/2)+1)="","market",INDEX(Positions!$R$6:$R$35,INT((ROW()-4)/2)+1)),IF(INDEX(Positions!$S$6:$S$35,INT((ROW()-4)/2)+1)="","market",INDEX(Positions!$S$6:$S$35,INT((ROW()-4)/2)+1)))) | G11: =IF(INDEX(Positions!$B$6:$B$35,INT((ROW()-4)/2)+1)="","",IF(MOD(ROW()-4,2)=0,INDEX(Positions!$G$6:$G$35,INT((ROW()-4)/2)+1),"")) | H11: =IF(INDEX(Positions!$B$6:$B$35,INT((ROW()-4)/2)+1)="","",IF(MOD(ROW()-4,2)=0,INDEX(Positions!$H$6:$H$35,INT((ROW()-4)/2)+1),"")) | I11: =IF(INDEX(Positions!$B$6:$B$35,INT((ROW()-4)/2)+1)="","",IF(MOD(ROW()-4,2)=0,INDEX(Positions!$A$6:$A$35,INT((ROW()-4)/2)+1),INDEX(Positions!$I$6:$I$35,INT((ROW()-4)/2)+1))) | J11: =IF(INDEX(Positions!$B$6:$B$35,INT((ROW()-4)/2)+1)="","",IF(MOD(ROW()-4,2)=0,IF(INDEX(Positions!$T$6:$T$35,INT((ROW()-4)/2)+1)="","filled",INDEX(Positions!$T$6:$T$35,INT((ROW()-4)/2)+1)),IF(INDEX(Positions!$U$6:$U$35,INT((ROW()-4)/2)+1)="","filled",INDEX(Positions!$U$6:$U$35,INT((ROW()-4)/2)+1)))) | K11: =IF(INDEX(Positions!$B$6:$B$35,INT((ROW()-4)/2)+1)="","",IF(MOD(ROW()-4,2)=0,INDEX(Positions!$V$6:$V$35,INT((ROW()-4)/2)+1),INDEX(Positions!$W$6:$W$35,INT((ROW()-4)/2)+1)))
A12: =IF(INDEX(Positions!$B$6:$B$35,INT((ROW()-4)/2)+1)="","",IF(MOD(ROW()-4,2)=0,INDEX(Positions!$A$6:$A$35,INT((ROW()-4)/2)+1),INDEX(Positions!$I$6:$I$35,INT((ROW()-4)/2)+1))) | B12: =IF(INDEX(Positions!$B$6:$B$35,INT((ROW()-4)/2)+1)="","",IF(MOD(ROW()-4,2)=0,IF(INDEX(Positions!$N$6:$N$35,INT((ROW()-4)/2)+1)="",INDEX(Positions!$B$6:$B$35,INT((ROW()-4)/2)+1)&"01",INDEX(Positions!$N$6:$N$35,INT((ROW()-4)/2)+1)),IF(INDEX(Positions!$O$6:$O$35,INT((ROW()-4)/2)+1)="",INDEX(Positions!$B$6:$B$35,INT((ROW()-4)/2)+1)&"02",INDEX(Positions!$O$6:$O$35,INT((ROW()-4)/2)+1)))) | C12: =IF(INDEX(Positions!$B$6:$B$35,INT((ROW()-4)/2)+1)="","",INDEX(Positions!$C$6:$C$35,INT((ROW()-4)/2)+1)) | D12: =IF(INDEX(Positions!$B$6:$B$35,INT((ROW()-4)/2)+1)="","",IF(MOD(ROW()-4,2)=0,INDEX(Positions!$D$6:$D$35,INT((ROW()-4)/2)+1),IF(INDEX(Positions!$D$6:$D$35,INT((ROW()-4)/2)+1)="buy","sell","buy"))) | E12: =IF(INDEX(Positions!$B$6:$B$35,INT((ROW()-4)/2)+1)="","",TEXT(INDEX(Positions!$E$6:$E$35,INT((ROW()-4)/2)+1),"0.00")&" / "&TEXT(INDEX(Positions!$E$6:$E$35,INT((ROW()-4)/2)+1),"0.00")) | F12: =IF(INDEX(Positions!$B$6:$B$35,INT((ROW()-4)/2)+1)="","",IF(MOD(ROW()-4,2)=0,IF(INDEX(Positions!$R$6:$R$35,INT((ROW()-4)/2)+1)="","market",INDEX(Positions!$R$6:$R$35,INT((ROW()-4)/2)+1)),IF(INDEX(Positions!$S$6:$S$35,INT((ROW()-4)/2)+1)="","market",INDEX(Positions!$S$6:$S$35,INT((ROW()-4)/2)+1)))) | G12: =IF(INDEX(Positions!$B$6:$B$35,INT((ROW()-4)/2)+1)="","",IF(MOD(ROW()-4,2)=0,INDEX(Positions!$G$6:$G$35,INT((ROW()-4)/2)+1),"")) | H12: =IF(INDEX(Positions!$B$6:$B$35,INT((ROW()-4)/2)+1)="","",IF(MOD(ROW()-4,2)=0,INDEX(Positions!$H$6:$H$35,INT((ROW()-4)/2)+1),"")) | I12: =IF(INDEX(Positions!$B$6:$B$35,INT((ROW()-4)/2)+1)="","",IF(MOD(ROW()-4,2)=0,INDEX(Positions!$A$6:$A$35,INT((ROW()-4)/2)+1),INDEX(Positions!$I$6:$I$35,INT((ROW()-4)/2)+1))) | J12: =IF(INDEX(Positions!$B$6:$B$35,INT((ROW()-4)/2)+1)="","",IF(MOD(ROW()-4,2)=0,IF(INDEX(Positions!$T$6:$T$35,INT((ROW()-4)/2)+1)="","filled",INDEX(Positions!$T$6:$T$35,INT((ROW()-4)/2)+1)),IF(INDEX(Positions!$U$6:$U$35,INT((ROW()-4)/2)+1)="","filled",INDEX(Positions!$U$6:$U$35,INT((ROW()-4)/2)+1)))) | K12: =IF(INDEX(Positions!$B$6:$B$35,INT((ROW()-4)/2)+1)="","",IF(MOD(ROW()-4,2)=0,INDEX(Positions!$V$6:$V$35,INT((ROW()-4)/2)+1),INDEX(Positions!$W$6:$W$35,INT((ROW()-4)/2)+1)))
A13: =IF(INDEX(Positions!$B$6:$B$35,INT((ROW()-4)/2)+1)="","",IF(MOD(ROW()-4,2)=0,INDEX(Positions!$A$6:$A$35,INT((ROW()-4)/2)+1),INDEX(Positions!$I$6:$I$35,INT((ROW()-4)/2)+1))) | B13: =IF(INDEX(Positions!$B$6:$B$35,INT((ROW()-4)/2)+1)="","",IF(MOD(ROW()-4,2)=0,IF(INDEX(Positions!$N$6:$N$35,INT((ROW()-4)/2)+1)="",INDEX(Positions!$B$6:$B$35,INT((ROW()-4)/2)+1)&"01",INDEX(Positions!$N$6:$N$35,INT((ROW()-4)/2)+1)),IF(INDEX(Positions!$O$6:$O$35,INT((ROW()-4)/2)+1)="",INDEX(Positions!$B$6:$B$35,INT((ROW()-4)/2)+1)&"02",INDEX(Positions!$O$6:$O$35,INT((ROW()-4)/2)+1)))) | C13: =IF(INDEX(Positions!$B$6:$B$35,INT((ROW()-4)/2)+1)="","",INDEX(Positions!$C$6:$C$35,INT((ROW()-4)/2)+1)) | D13: =IF(INDEX(Positions!$B$6:$B$35,INT((ROW()-4)/2)+1)="","",IF(MOD(ROW()-4,2)=0,INDEX(Positions!$D$6:$D$35,INT((ROW()-4)/2)+1),IF(INDEX(Positions!$D$6:$D$35,INT((ROW()-4)/2)+1)="buy","sell","buy"))) | E13: =IF(INDEX(Positions!$B$6:$B$35,INT((ROW()-4)/2)+1)="","",TEXT(INDEX(Positions!$E$6:$E$35,INT((ROW()-4)/2)+1),"0.00")&" / "&TEXT(INDEX(Positions!$E$6:$E$35,INT((ROW()-4)/2)+1),"0.00")) | F13: =IF(INDEX(Positions!$B$6:$B$35,INT((ROW()-4)/2)+1)="","",IF(MOD(ROW()-4,2)=0,IF(INDEX(Positions!$R$6:$R$35,INT((ROW()-4)/2)+1)="","market",INDEX(Positions!$R$6:$R$35,INT((ROW()-4)/2)+1)),IF(INDEX(Positions!$S$6:$S$35,INT((ROW()-4)/2)+1)="","market",INDEX(Positions!$S$6:$S$35,INT((ROW()-4)/2)+1)))) | G13: =IF(INDEX(Positions!$B$6:$B$35,INT((ROW()-4)/2)+1)="","",IF(MOD(ROW()-4,2)=0,INDEX(Positions!$G$6:$G$35,INT((ROW()-4)/2)+1),"")) | H13: =IF(INDEX(Positions!$B$6:$B$35,INT((ROW()-4)/2)+1)="","",IF(MOD(ROW()-4,2)=0,INDEX(Positions!$H$6:$H$35,INT((ROW()-4)/2)+1),"")) | I13: =IF(INDEX(Positions!$B$6:$B$35,INT((ROW()-4)/2)+1)="","",IF(MOD(ROW()-4,2)=0,INDEX(Positions!$A$6:$A$35,INT((ROW()-4)/2)+1),INDEX(Positions!$I$6:$I$35,INT((ROW()-4)/2)+1))) | J13: =IF(INDEX(Positions!$B$6:$B$35,INT((ROW()-4)/2)+1)="","",IF(MOD(ROW()-4,2)=0,IF(INDEX(Positions!$T$6:$T$35,INT((ROW()-4)/2)+1)="","filled",INDEX(Positions!$T$6:$T$35,INT((ROW()-4)/2)+1)),IF(INDEX(Positions!$U$6:$U$35,INT((ROW()-4)/2)+1)="","filled",INDEX(Positions!$U$6:$U$35,INT((ROW()-4)/2)+1)))) | K13: =IF(INDEX(Positions!$B$6:$B$35,INT((ROW()-4)/2)+1)="","",IF(MOD(ROW()-4,2)=0,INDEX(Positions!$V$6:$V$35,INT((ROW()-4)/2)+1),INDEX(Positions!$W$6:$W$35,INT((ROW()-4)/2)+1)))
A14: =IF(INDEX(Positions!$B$6:$B$35,INT((ROW()-4)/2)+1)="","",IF(MOD(ROW()-4,2)=0,INDEX(Positions!$A$6:$A$35,INT((ROW()-4)/2)+1),INDEX(Positions!$I$6:$I$35,INT((ROW()-4)/2)+1))) | B14: =IF(INDEX(Positions!$B$6:$B$35,INT((ROW()-4)/2)+1)="","",IF(MOD(ROW()-4,2)=0,IF(INDEX(Positions!$N$6:$N$35,INT((ROW()-4)/2)+1)="",INDEX(Positions!$B$6:$B$35,INT((ROW()-4)/2)+1)&"01",INDEX(Positions!$N$6:$N$35,INT((ROW()-4)/2)+1)),IF(INDEX(Positions!$O$6:$O$35,INT((ROW()-4)/2)+1)="",INDEX(Positions!$B$6:$B$35,INT((ROW()-4)/2)+1)&"02",INDEX(Positions!$O$6:$O$35,INT((ROW()-4)/2)+1)))) | C14: =IF(INDEX(Positions!$B$6:$B$35,INT((ROW()-4)/2)+1)="","",INDEX(Positions!$C$6:$C$35,INT((ROW()-4)/2)+1)) | D14: =IF(INDEX(Positions!$B$6:$B$35,INT((ROW()-4)/2)+1)="","",IF(MOD(ROW()-4,2)=0,INDEX(Positions!$D$6:$D$35,INT((ROW()-4)/2)+1),IF(INDEX(Positions!$D$6:$D$35,INT((ROW()-4)/2)+1)="buy","sell","buy"))) | E14: =IF(INDEX(Positions!$B$6:$B$35,INT((ROW()-4)/2)+1)="","",TEXT(INDEX(Positions!$E$6:$E$35,INT((ROW()-4)/2)+1),"0.00")&" / "&TEXT(INDEX(Positions!$E$6:$E$35,INT((ROW()-4)/2)+1),"0.00")) | F14: =IF(INDEX(Positions!$B$6:$B$35,INT((ROW()-4)/2)+1)="","",IF(MOD(ROW()-4,2)=0,IF(INDEX(Positions!$R$6:$R$35,INT((ROW()-4)/2)+1)="","market",INDEX(Positions!$R$6:$R$35,INT((ROW()-4)/2)+1)),IF(INDEX(Positions!$S$6:$S$35,INT((ROW()-4)/2)+1)="","market",INDEX(Positions!$S$6:$S$35,INT((ROW()-4)/2)+1)))) | G14: =IF(INDEX(Positions!$B$6:$B$35,INT((ROW()-4)/2)+1)="","",IF(MOD(ROW()-4,2)=0,INDEX(Positions!$G$6:$G$35,INT((ROW()-4)/2)+1),"")) | H14: =IF(INDEX(Positions!$B$6:$B$35,INT((ROW()-4)/2)+1)="","",IF(MOD(ROW()-4,2)=0,INDEX(Positions!$H$6:$H$35,INT((ROW()-4)/2)+1),"")) | I14: =IF(INDEX(Positions!$B$6:$B$35,INT((ROW()-4)/2)+1)="","",IF(MOD(ROW()-4,2)=0,INDEX(Positions!$A$6:$A$35,INT((ROW()-4)/2)+1),INDEX(Positions!$I$6:$I$35,INT((ROW()-4)/2)+1))) | J14: =IF(INDEX(Positions!$B$6:$B$35,INT((ROW()-4)/2)+1)="","",IF(MOD(ROW()-4,2)=0,IF(INDEX(Positions!$T$6:$T$35,INT((ROW()-4)/2)+1)="","filled",INDEX(Positions!$T$6:$T$35,INT((ROW()-4)/2)+1)),IF(INDEX(Positions!$U$6:$U$35,INT((ROW()-4)/2)+1)="","filled",INDEX(Positions!$U$6:$U$35,INT((ROW()-4)/2)+1)))) | K14: =IF(INDEX(Positions!$B$6:$B$35,INT((ROW()-4)/2)+1)="","",IF(MOD(ROW()-4,2)=0,INDEX(Positions!$V$6:$V$35,INT((ROW()-4)/2)+1),INDEX(Positions!$W$6:$W$35,INT((ROW()-4)/2)+1)))
A15: =IF(INDEX(Positions!$B$6:$B$35,INT((ROW()-4)/2)+1)="","",IF(MOD(ROW()-4,2)=0,INDEX(Positions!$A$6:$A$35,INT((ROW()-4)/2)+1),INDEX(Positions!$I$6:$I$35,INT((ROW()-4)/2)+1))) | B15: =IF(INDEX(Positions!$B$6:$B$35,INT((ROW()-4)/2)+1)="","",IF(MOD(ROW()-4,2)=0,IF(INDEX(Positions!$N$6:$N$35,INT((ROW()-4)/2)+1)="",INDEX(Positions!$B$6:$B$35,INT((ROW()-4)/2)+1)&"01",INDEX(Positions!$N$6:$N$35,INT((ROW()-4)/2)+1)),IF(INDEX(Positions!$O$6:$O$35,INT((ROW()-4)/2)+1)="",INDEX(Positions!$B$6:$B$35,INT((ROW()-4)/2)+1)&"02",INDEX(Positions!$O$6:$O$35,INT((ROW()-4)/2)+1)))) | C15: =IF(INDEX(Positions!$B$6:$B$35,INT((ROW()-4)/2)+1)="","",INDEX(Positions!$C$6:$C$35,INT((ROW()-4)/2)+1)) | D15: =IF(INDEX(Positions!$B$6:$B$35,INT((ROW()-4)/2)+1)="","",IF(MOD(ROW()-4,2)=0,INDEX(Positions!$D$6:$D$35,INT((ROW()-4)/2)+1),IF(INDEX(Positions!$D$6:$D$35,INT((ROW()-4)/2)+1)="buy","sell","buy"))) | E15: =IF(INDEX(Positions!$B$6:$B$35,INT((ROW()-4)/2)+1)="","",TEXT(INDEX(Positions!$E$6:$E$35,INT((ROW()-4)/2)+1),"0.00")&" / "&TEXT(INDEX(Positions!$E$6:$E$35,INT((ROW()-4)/2)+1),"0.00")) | F15: =IF(INDEX(Positions!$B$6:$B$35,INT((ROW()-4)/2)+1)="","",IF(MOD(ROW()-4,2)=0,IF(INDEX(Positions!$R$6:$R$35,INT((ROW()-4)/2)+1)="","market",INDEX(Positions!$R$6:$R$35,INT((ROW()-4)/2)+1)),IF(INDEX(Positions!$S$6:$S$35,INT((ROW()-4)/2)+1)="","market",INDEX(Positions!$S$6:$S$35,INT((ROW()-4)/2)+1)))) | G15: =IF(INDEX(Positions!$B$6:$B$35,INT((ROW()-4)/2)+1)="","",IF(MOD(ROW()-4,2)=0,INDEX(Positions!$G$6:$G$35,INT((ROW()-4)/2)+1),"")) | H15: =IF(INDEX(Positions!$B$6:$B$35,INT((ROW()-4)/2)+1)="","",IF(MOD(ROW()-4,2)=0,INDEX(Positions!$H$6:$H$35,INT((ROW()-4)/2)+1),"")) | I15: =IF(INDEX(Positions!$B$6:$B$35,INT((ROW()-4)/2)+1)="","",IF(MOD(ROW()-4,2)=0,INDEX(Positions!$A$6:$A$35,INT((ROW()-4)/2)+1),INDEX(Positions!$I$6:$I$35,INT((ROW()-4)/2)+1))) | J15: =IF(INDEX(Positions!$B$6:$B$35,INT((ROW()-4)/2)+1)="","",IF(MOD(ROW()-4,2)=0,IF(INDEX(Positions!$T$6:$T$35,INT((ROW()-4)/2)+1)="","filled",INDEX(Positions!$T$6:$T$35,INT((ROW()-4)/2)+1)),IF(INDEX(Positions!$U$6:$U$35,INT((ROW()-4)/2)+1)="","filled",INDEX(Positions!$U$6:$U$35,INT((ROW()-4)/2)+1)))) | K15: =IF(INDEX(Positions!$B$6:$B$35,INT((ROW()-4)/2)+1)="","",IF(MOD(ROW()-4,2)=0,INDEX(Positions!$V$6:$V$35,INT((ROW()-4)/2)+1),INDEX(Positions!$W$6:$W$35,INT((ROW()-4)/2)+1)))
... A63: =IF(INDEX(Positions!$B$6:$B$35,INT((ROW()-4)/2)+1)="","",IF(MOD(ROW()-4,2)=0,INDEX(Positions!$A$6:$A$35,INT((ROW()-4)/2)+1),INDEX(Positions!$I$6:$I$35,INT((ROW()-4)/2)+1))) | B63: =IF(INDEX(Positions!$B$6:$B$35,INT((ROW()-4)/2)+1)="","",IF(MOD(ROW()-4,2)=0,IF(INDEX(Positions!$N$6:$N$35,INT((ROW()-4)/2)+1)="",INDEX(Positions!$B$6:$B$35,INT((ROW()-4)/2)+1)&"01",INDEX(Positions!$N$6:$N$35,INT((ROW()-4)/2)+1)),IF(INDEX(Positions!$O$6:$O$35,INT((ROW()-4)/2)+1)="",INDEX(Positions!$B$6:$B$35,INT((ROW()-4)/2)+1)&"02",INDEX(Positions!$O$6:$O$35,INT((ROW()-4)/2)+1)))) | C63: =IF(INDEX(Positions!$B$6:$B$35,INT((ROW()-4)/2)+1)="","",INDEX(Positions!$C$6:$C$35,INT((ROW()-4)/2)+1)) | D63: =IF(INDEX(Positions!$B$6:$B$35,INT((ROW()-4)/2)+1)="","",IF(MOD(ROW()-4,2)=0,INDEX(Positions!$D$6:$D$35,INT((ROW()-4)/2)+1),IF(INDEX(Positions!$D$6:$D$35,INT((ROW()-4)/2)+1)="buy","sell","buy"))) | E63: =IF(INDEX(Positions!$B$6:$B$35,INT((ROW()-4)/2)+1)="","",TEXT(INDEX(Positions!$E$6:$E$35,INT((ROW()-4)/2)+1),"0.00")&" / "&TEXT(INDEX(Positions!$E$6:$E$35,INT((ROW()-4)/2)+1),"0.00")) | F63: =IF(INDEX(Positions!$B$6:$B$35,INT((ROW()-4)/2)+1)="","",IF(MOD(ROW()-4,2)=0,IF(INDEX(Positions!$R$6:$R$35,INT((ROW()-4)/2)+1)="","market",INDEX(Positions!$R$6:$R$35,INT((ROW()-4)/2)+1)),IF(INDEX(Positions!$S$6:$S$35,INT((ROW()-4)/2)+1)="","market",INDEX(Positions!$S$6:$S$35,INT((ROW()-4)/2)+1)))) | G63: =IF(INDEX(Positions!$B$6:$B$35,INT((ROW()-4)/2)+1)="","",IF(MOD(ROW()-4,2)=0,INDEX(Positions!$G$6:$G$35,INT((ROW()-4)/2)+1),"")) | H63: =IF(INDEX(Positions!$B$6:$B$35,INT((ROW()-4)/2)+1)="","",IF(MOD(ROW()-4,2)=0,INDEX(Positions!$H$6:$H$35,INT((ROW()-4)/2)+1),"")) | I63: =IF(INDEX(Positions!$B$6:$B$35,INT((ROW()-4)/2)+1)="","",IF(MOD(ROW()-4,2)=0,INDEX(Positions!$A$6:$A$35,INT((ROW()-4)/2)+1),INDEX(Positions!$I$6:$I$35,INT((ROW()-4)/2)+1))) | J63: =IF(INDEX(Positions!$B$6:$B$35,INT((ROW()-4)/2)+1)="","",IF(MOD(ROW()-4,2)=0,IF(INDEX(Positions!$T$6:$T$35,INT((ROW()-4)/2)+1)="","filled",INDEX(Positions!$T$6:$T$35,INT((ROW()-4)/2)+1)),IF(INDEX(Positions!$U$6:$U$35,INT((ROW()-4)/2)+1)="","filled",INDEX(Positions!$U$6:$U$35,INT((ROW()-4)/2)+1)))) | K63: =IF(INDEX(Positions!$B$6:$B$35,INT((ROW()-4)/2)+1)="","",IF(MOD(ROW()-4,2)=0,INDEX(Positions!$V$6:$V$35,INT((ROW()-4)/2)+1),INDEX(Positions!$W$6:$W$35,INT((ROW()-4)/2)+1)))

Sheet Deals_Auto
A1: Deals (auto from Positions)
A3: Time | B3: Deal | C3: Symbol | D3: Type | E3: Direction | F3: Volume | G3: Price | H3: Order | I3: Cost | J3: Commission | K3: Fee | L3: Swap | M3: Profit | N3: Balance | O3: Comment
A4: 46055.417 | B4: 784380249 | D4: balance | J4: 0 | K4: 0 | L4: 0 | M4: 88.15 | N4: 88.15 | O4: TR #13341666|
A5: =IF(INDEX(Positions!$B$6:$B$35,INT((ROW()-5)/2)+1)="","",IF(MOD(ROW()-5,2)=0,INDEX(Positions!$A$6:$A$35,INT((ROW()-5)/2)+1),INDEX(Positions!$I$6:$I$35,INT((ROW()-5)/2)+1))) | B5: =IF(INDEX(Positions!$B$6:$B$35,INT((ROW()-5)/2)+1)="","",IF(MOD(ROW()-5,2)=0,IF(INDEX(Positions!$P$6:$P$35,INT((ROW()-5)/2)+1)="",INDEX(Positions!$B$6:$B$35,INT((ROW()-5)/2)+1)&"11",INDEX(Positions!$P$6:$P$35,INT((ROW()-5)/2)+1)),IF(INDEX(Positions!$Q$6:$Q$35,INT((ROW()-5)/2)+1)="",INDEX(Positions!$B$6:$B$35,INT((ROW()-5)/2)+1)&"12",INDEX(Positions!$Q$6:$Q$35,INT((ROW()-5)/2)+1)))) | C5: =IF(INDEX(Positions!$B$6:$B$35,INT((ROW()-5)/2)+1)="","",INDEX(Positions!$C$6:$C$35,INT((ROW()-5)/2)+1)) | D5: =IF(INDEX(Positions!$B$6:$B$35,INT((ROW()-5)/2)+1)="","",IF(MOD(ROW()-5,2)=0,INDEX(Positions!$D$6:$D$35,INT((ROW()-5)/2)+1),IF(INDEX(Positions!$D$6:$D$35,INT((ROW()-5)/2)+1)="buy","sell","buy"))) | E5: =IF(INDEX(Positions!$B$6:$B$35,INT((ROW()-5)/2)+1)="","",IF(MOD(ROW()-5,2)=0,"in","out")) | F5: =IF(INDEX(Positions!$B$6:$B$35,INT((ROW()-5)/2)+1)="","",INDEX(Positions!$E$6:$E$35,INT((ROW()-5)/2)+1)) | G5: =IF(INDEX(Positions!$B$6:$B$35,INT((ROW()-5)/2)+1)="","",IF(MOD(ROW()-5,2)=0,INDEX(Positions!$F$6:$F$35,INT((ROW()-5)/2)+1),INDEX(Positions!$J$6:$J$35,INT((ROW()-5)/2)+1))) | H5: =IF(INDEX(Positions!$B$6:$B$35,INT((ROW()-5)/2)+1)="","",IF(MOD(ROW()-5,2)=0,IF(INDEX(Positions!$N$6:$N$35,INT((ROW()-5)/2)+1)="",INDEX(Positions!$B$6:$B$35,INT((ROW()-5)/2)+1)&"01",INDEX(Positions!$N$6:$N$35,INT((ROW()-5)/2)+1)),IF(INDEX(Positions!$O$6:$O$35,INT((ROW()-5)/2)+1)="",INDEX(Positions!$B$6:$B$35,INT((ROW()-5)/2)+1)&"02",INDEX(Positions!$O$6:$O$35,INT((ROW()-5)/2)+1)))) | I5: =0 | J5: =IF(INDEX(Positions!$B$6:$B$35,INT((ROW()-5)/2)+1)="","",IF(MOD(ROW()-5,2)=0,0,INDEX(Positions!$K$6:$K$35,INT((ROW()-5)/2)+1))) | K5: =IF(INDEX(Positions!$B$6:$B$35,INT((ROW()-5)/2)+1)="","",IF(MOD(ROW()-5,2)=0,0,INDEX(Positions!$X$6:$X$35,INT((ROW()-5)/2)+1))) | L5: =IF(INDEX(Positions!$B$6:$B$35,INT((ROW()-5)/2)+1)="","",IF(MOD(ROW()-5,2)=0,0,INDEX(Positions!$L$6:$L$35,INT((ROW()-5)/2)+1))) | M5: =IF(INDEX(Positions!$B$6:$B$35,INT((ROW()-5)/2)+1)="","",IF(MOD(ROW()-5,2)=0,0,INDEX(Positions!$M$6:$M$35,INT((ROW()-5)/2)+1))) | N5: =IF(INDEX(Positions!$B$6:$B$35,INT((ROW()-5)/2)+1)="","",IF(MOD(ROW()-5,2)=0,INDEX(Positions!$Z$6:$Z$35,INT((ROW()-5)/2)+1),INDEX(Positions!$AA$6:$AA$35,INT((ROW()-5)/2)+1))) | O5: =IF(INDEX(Positions!$B$6:$B$35,INT((ROW()-5)/2)+1)="","",IF(MOD(ROW()-5,2)=0,INDEX(Positions!$V$6:$V$35,INT((ROW()-5)/2)+1),INDEX(Positions!$W$6:$W$35,INT((ROW()-5)/2)+1)))
